Workbook

Sheet A201
B3: SENARAI PENAWARAN KURSUS MENGIKUT SEMESTER
B4: SARJANA MUDA KEJURUTERAAN ELEKTRONIK DENGAN KEPUJIAN
B5: SESI AKADEMIK 2021/2022
B7: Semester | C7: Kod kursus | D7: Nama kursus | E7: Taraf kursus | F7: Jam Kredit | H7: Gred | J7: Gred Unit | K7: GPA | L7: GPA
B8: I | C8: BAA1022 | D8: Bahasa Arab Praktikal | E8: WF | F8: 2 | G8: =4*F8 -> 8 | H8: A | I8: =IF(H8<>"",HLOOKUP(H8,'GPA Table'!B5:M8,2,FALSE ),"") -> 4 | J8: =I8*F8 -> 8
C9: BAA2022 | D9: Bahasa Arab Komunikasi | E9: WF
C10: BAA3022 | D10: Bahasa Arab Sains | E10: WF
C11: BIA1012 | D11: Kemahiran Am Bahasa Inggeris | E11: WF | F11: 2 | G11: =4*F11 -> 8 | H11: A | I11: =IF(H11<>"",HLOOKUP(H11,'GPA Table'!$B$5:$M$8,2,FALSE ),"") -> 4 | J11: =I11*F11 -> 8
C12: BIA2012 | D12: Bahasa Inggeris untuk Komunikasi | E12: WF
C13: BIS4022 | D13: Bahasa Inggeris untuk Keperluan Profesional | E13: WF
C14: BIS5012 | D14: Bahasa Inggeris untuk Keperluan Penyelidikan | E14: WF
C15: UTC1012 | D15: Penghayatan Etika dan Peradaban | E15: WU | F15: 2 | G15: =4*F15 -> 8 | H15: A | I15: =IF(H15<>"",HLOOKUP(H15,'GPA Table'!$B$5:$M$8,2,FALSE ),"") -> 4 | J15: =I15*F15 -> 8
C16: UBY1012 | D16: Bahasa Melayu Komunikasi* | E16: WU
C17: UTT3012 | D17: Pengantar Kitab Turath | E17: WU | G17: =4*F17 -> 0 | H17: A | I17: =IF(H17<>"",HLOOKUP(H17,'GPA Table'!$B$5:$M$8,2,FALSE ),"") -> 4 | J17: =I17*F17 -> 0
C18: KEE1133 | D18: Teknologi Elektrik | E18: WF | F18: 3 | G18: =4*F18 -> 12 | H18: A | I18: =IF(H18<>"",HLOOKUP(H18,'GPA Table'!$B$5:$M$8,2,FALSE ),"") -> 4 | J18: =I18*F18 -> 12
C19: KEH1123 | D19: Matematik Kejuruteraan I | E19: WF | F19: 3 | G19: =4*F19 -> 12 | H19: A | I19: =IF(H19<>"",HLOOKUP(H19,'GPA Table'!$B$5:$M$8,2,FALSE ),"") -> 4 | J19: =I19*F19 -> 12
C20: KEK1113 | D20: Pengaturcaraan untuk Kejuruteraan | E20: WF | F20: 3 | G20: =4*F20 -> 12 | H20: A | I20: =IF(H20<>"",HLOOKUP(H20,'GPA Table'!$B$5:$M$8,2,FALSE ),"") -> 4 | J20: =I20*F20 -> 12
C21: *For international student only | F21: =SUM(F8:F20) -> 15 | G21: =SUM(G8:G20) -> 60 | I21: =SUM(I8:I20) -> 28 | J21: =SUM(J8:J20) -> 60 | K21: =J21/G21*4 -> 4 | L21: =K21 -> 4
B22: II | C22: BAA2022 | D22: Bahasa Arab Komunikasi | E22: WF | F22: 2 | G22: =F22*4 -> 8 | H22: A | I22: =IF(H22<>"",HLOOKUP(H22,'GPA Table'!$B$5:$M$8,2,FALSE ),"") -> 4 | J22: =I22*F22 -> 8
C23: BAA3022 | D23: Bahasa Arab Sains | E23: WF
C24: BAA5012 | D24: Bahasa Arab Profesional | E24: WF
C25: BIA2012 | D25: Bahasa Inggeris untuk Komunikasi | E25: WF | F25: 2 | G25: =F25*4 -> 8 | H25: A | I25: =IF(H25<>"",HLOOKUP(H25,'GPA Table'!$B$5:$M$8,2,FALSE ),"") -> 4 | J25: =I25*F25 -> 8
C26: BIA3012 | D26: Bahasa Inggeris untuk Keperluan Akademik | E26: WF
C27: BIS5012 | D27: Bahasa Inggeris untuk Keperluan Penyelidikan | E27: WF
C28: UTP1012 | D28: Falsafah dan Isu Semasa | E28: WU | F28: 2 | G28: =F28*4 -> 8 | H28: A | I28: =IF(H28<>"",HLOOKUP(H28,'GPA Table'!$B$5:$M$8,2,FALSE ),"") -> 4 | J28: =I28*F28 -> 8
C29: UTC1022 | D29: Ethics and Civilization* | E29: WU
C30: KEE1223 | D30: Rekabentuk Logik | E30: WF | F30: 3 | G30: =F30*4 -> 12 | H30: A | I30: =IF(H30<>"",HLOOKUP(H30,'GPA Table'!$B$5:$M$8,2,FALSE ),"") -> 4 | J30: =I30*F30 -> 12
C31: KEE1243 | D31: Peranti Elektronik Analog | E31: WF | F31: 3 | G31: =F31*4 -> 12 | H31: A | I31: =IF(H31<>"",HLOOKUP(H31,'GPA Table'!$B$5:$M$8,2,FALSE ),"") -> 4 | J31: =I31*F31 -> 12
C32: KEE1253 | D32: Instrumentasi dan Pengukuran | E32: WF | F32: 3 | G32: =F32*4 -> 12 | H32: A | I32: =IF(H32<>"",HLOOKUP(H32,'GPA Table'!$B$5:$M$8,2,FALSE ),"") -> 4 | J32: =I32*F32 -> 12
C33: KEH1213 | D33: Matematik Kejuruteraan II | E33: WF | F33: 3 | G33: =F33*4 -> 12 | H33: A | I33: =IF(H33<>"",HLOOKUP(H33,'GPA Table'!$B$5:$M$8,2,FALSE ),"") -> 4 | J33: =I33*F33 -> 12
C34: *For international student only | F34: =SUM(F22:F33) -> 18 | G34: =SUM(G22:G33) -> 72 | I34: =SUM(I22:I33) -> 28 | J34: =SUM(J22:J33) -> 72 | K34: =J34/G34*4 -> 4 | L34: =(K34+K21)/2 -> 4
B35: III | C35: BIA3012 | D35: Bahasa Inggeris untuk Keperluan Akademik | E35: WF | F35: 2 | G35: =F35*4 -> 8 | H35: A | I35: =IF(H35<>"",HLOOKUP(H35,'GPA Table'!$B$5:$M$8,2,FALSE ),"") -> 4 | J35: =I35*F35 -> 8
C36: BIS4022 | D36: Bahasa Inggeris untuk Keperluan Profesional | E36: WF
C37: KEE2333 | D37: Rekabentuk Litar Elektronik | E37: WF | F37: 3 | G37: =F37*4 -> 12 | H37: A | I37: =IF(H37<>"",HLOOKUP(H37,'GPA Table'!$B$5:$M$8,2,FALSE ),"") -> 4 | J37: =I37*F37 -> 12
C38: KEE2343 | D38: Kejuruteraan Kuasa Elektrik | E38: WF | F38: 3 | G38: =F38*4 -> 12 | H38: A | I38: =IF(H38<>"",HLOOKUP(H38,'GPA Table'!$B$5:$M$8,2,FALSE ),"") -> 4 | J38: =I38*F38 -> 12
C39: KEE2353 | D39: Amalan Kejuruteraan | E39: WF | F39: 3 | G39: =F39*4 -> 12 | H39: A | I39: =IF(H39<>"",HLOOKUP(H39,'GPA Table'!$B$5:$M$8,2,FALSE ),"") -> 4 | J39: =I39*F39 -> 12
C40: KEE2363 | D40: Peranti Penderia | E40: WF | F40: 3 | G40: =F40*4 -> 12 | H40: A | I40: =IF(H40<>"",HLOOKUP(H40,'GPA Table'!$B$5:$M$8,2,FALSE ),"") -> 4 | J40: =I40*F40 -> 12
C41: KEH2323 | D41: Kaedah Berangka untuk Kejuruteraan | E41: WF | F41: 3 | G41: =F41*4 -> 12 | H41: A | I41: =IF(H41<>"",HLOOKUP(H41,'GPA Table'!$B$5:$M$8,2,FALSE ),"") -> 4 | J41: =I41*F41 -> 12
F42: =SUM(F35:F41) -> 17 | G42: =SUM(G35:G41) -> 68 | I42: =SUM(I35:I41) -> 24 | J42: =SUM(J35:J41) -> 68 | K42: =J42/G42*4 -> 4 | L42: =(K34+K21+K42)/3 -> 4
B43: IV | C43: UTU3012 | D43: Keusahawanan | E43: WU | F43: 2 | G43: =F43*4 -> 8 | H43: A | I43: =IF(H43<>"",HLOOKUP(H43,'GPA Table'!$B$5:$M$8,2,FALSE ),"") -> 4 | J43: =I43*F43 -> 8
...

Sheet GPA Table
B4: Grade & GPA Table
B5: Letter Grade | C5: F | D5: D | E5: C- | F5: C | G5: C+ | H5: B- | I5: B | J5: B+ | K5: A- | L5: A | M5: A+
B6: GPA | C6: 0 | D6: 1 | E6: 1.75 | F6: 2 | G6: 2.5 | H6: 2.75 | I6: 3 | J6: 3.5 | K6: 3.75 | L6: 4 | M6: 4
B7: Passing | C7: Fail | D7: Fail | E7: Fail | F7: Pass | G7: Pass | H7: Pass | I7: Pass | J7: Pass | K7: Pass | L7: Pass | M7: Pass
B8: University Level | C8: Fail | D8: Fail | E8: Fail | F8: Pass | G8: Satisfactory | H8: Satisfactory | I8: Good | J8: Good | K8: Excellent | L8: Excellent | M8: Distinction
